Workbook

Sheet PLAN CONCERTADO
A1: FORMATO PLAN CONCERTADO DE LA RUTA DE APRENDIZAJE
A2: Instructor | D2: EDWIN ALBEIRO RAMOS VILLAMIL | P2: Trimestre del año | T2: III
A3: Programa de Formación | F3: ANÁLISIS Y DESARROLLO DE SOFTWARE | P3: Trimestre Formación | T3: V
A4: Nivel | C4: TECNÓLOGO | E4: Ficha | G4: 2996150 | J4: Jornada | M4: DIURNA | P4: Fecha Concertación | T4: 45866
A7: Aprendiz | G7: Competencia | O7: Resultado de Aprendizaje | W7: Temática | AB7: Evidencia de Aprendizaje | AH7: Tipo de Evidencia | AK7: Formato de Entrega | AM7: Fecha de Entrega | AO7: Entregó
AH8: EC | AI8: ED | AJ8: EP | AK8: Físico | AL8: Digital | AO8: Sí | AP8: No
A9: 1 | B9: JUAN CAMILO AREVALO ROA | G9: ( COMPETENCIAS TÉCNICAS TRANSVERSALES) | O9: ( RESULTADOS DE APRENDIZAJE DEL TRIMESTRE ) | W9: Presentación del Trimestre: Instructor, Competencias, Resultados, Evidencias, Metodología, Normas y Seguimiento Académico. | AB9: Cronograma de Actividades | AH9: X | AI9: X | AJ9: X | AL9: X | AM9: 45873 | AP9: X
A10: 2 | B10: DANIELA LORENA BOHORQUEZ DIAZ | W10: Ajustar el Portafolio del Aprendiz | AB10: Portafolio del Aprendiz con Evidencias de los Trimestres | AH10: X | AI10: X | AJ10: X | AL10: X | AM10: 45873 | AP10: X
A11: 3 | B11: JHONATAN CARVAJAL BONILLA | W11: Organizar el Sistema Control de Versiones | AB11: Sistema Control Versiones con Entregables Proyecto | AH11: X | AI11: X | AJ11: X | AL11: X | AM11: 45873 | AP11: X
A12: 4 | B12: PAULA ANDREA CASSIANI CASTILLO | W12: Verificar la calidad de las evidencias del proyecto software de trimestres anteriores | AB12: Evidencias del Proyecto de Trimestres Anteriores | AH12: X | AI12: X | AJ12: X | AL12: X | AM12: 45873 | AP12: X
A13: 5 | B13: DANIEL CASTILLO MORA | G13: 220501096 DESARROLLAR LA SOLUCIÓN DE SOFTWARE DE ACUERDO CON EL DISEÑO Y METODOLOGÍAS DE DESARROLLO | O13: 220501096_04 CODIFICAR EL SOFTWARE DE ACUERDO CON EL DISEÑO ESTABLECIDO | W13: Desarrollar las API REST de la aplicación web | AB13: API REST | AH13: X | AI13: X | AL13: X | AM13: 45894 | AP13: X
A14: 6 | B14: YOJAN SNEYDER FLOREZ SANCHEZ | W14: Desarrollo de Frontend de la aplicación web con React, Angular o Vue basado en el diseño web | AB14: Frontend JS | AH14: X | AI14: X | AL14: X | AM14: 45894 | AP14: X
A15: 7 | B15: DAVID SANTIAGO FUQUENE LEAL | W15: Incorporar seguridad a la API REST de la aplicación web | AB15: API REST Segura | AH15: X | AI15: X | AL15: X | AM15: 45915 | AP15: X
A16: 8 | B16: OSCAR DAVID GELPUD ERAZO | W16: Desarrollar la aplicación web | AB16: Aplicación Web (80%) | AH16: X | AI16: X | AL16: X | AM16: 45915 | AP16: X
A17: 9 | B17: KAREN DANIELA LEAL POVEDA | G17: ( COMPETENCIAS DEL TRIMESTRE ) | O17: ( RESULTADOS DE APRENDIZAJE DEL TRIMESTRE ) | W17: EVALUACIÓN DE CONOCIMIENTO | AB17: Presentación Evaluación de Conocimiento | AH17: X | AL17: X | AM17: 45915 | AP17: X
A18: 10 | B18: DAYANA MACHADO MUÑOZ | W18: PRE-SUSTENTACIÓN | AB18: Entregables Proyecto | AI18: X | AL18: X | AM18: 45922 | AP18: X
A19: 11 | B19: JUAN SEBASTIAN MARTINEZ PINTO | W19: SUSTENTACIÓN | AB19: Entregables Proyecto | AI19: X | AL19: X | AM19: 45924 | AP19: X
A20: 12 | B20: NICOLAS MARTINEZ VALENZUELA | W20: AJUSTES PROYECTO Y CIERRE DE TRIMESTRE | AB20: Ajuste de los entregables del Proyecto | AI20: X | AL20: X | AM20: 45936 | AP20: X
A21: 13 | B21: JUAN SEBASTIAN MOLINA CIFUENTES
A22: 14 | B22: KATHERIN MORCILLO QUIROGA
A23: 15 | B23: JAIDER SEBASTIAN MORENO QUINTERO
A24: 16 | B24: BRYAN MUÑOZ RODRIGUEZ
A25: 17 | B25: JOHAN FERNANDO OCHOA LOZANO
A26: 18 | B26: DUVIER OLMOS COMETA
A27: 19 | B27: BRAYAN SANTIAGO RACHEN CARDENAS
A28: 20 | B28: DANNA VALENTINA RODRIGUEZ CLAVIJO
A29: 21 | B29: SARA RUIZ LOPEZ
A30: 22 | B30: DEREK YHOSEPH SAAVEDRA CASTAÑEDA
A31: 23 | B31: MICHAEL STEVEN SALAMANCA MARTIN
A32: 24 | B32: VALENTINA SIERRA SANCHEZ
... A37: 29 | B37: SIMON ESTEBAN VARGAS MORA

Sheet 1
A1: FORMATO PLAN CONCERTADO DE LA RUTA DE APRENDIZAJE
A2: Instructor | D2: EDWIN ALBEIRO RAMOS VILLAMIL | P2: Trimestre del año | T2: III
A3: Programa de Formación | F3: ANÁLISIS Y DESARROLLO DE SOFTWARE | P3: Trimestre Formación | T3: V
A4: Nivel | C4: TECNÓLOGO | E4: Ficha | G4: 2996150 | J4: Jornada | M4: DIURNA | P4: Fecha Concertación | T4: 45866
A7: Aprendiz | G7: Competencia | O7: Resultado de Aprendizaje | W7: Temática | AB7: Evidencia de Aprendizaje | AH7: Tipo de Evidencia | AK7: Formato de Entrega | AM7: Fecha de Entrega | AO7: Entregó
AH8: EC | AI8: ED | AJ8: EP | AK8: Físico | AL8: Digital | AO8: Sí | AP8: No
A9: ='PLAN CONCERTADO'!B9 -> JUAN CAMILO AREVALO ROA | G9: ='PLAN CONCERTADO'!G9 -> ( COMPETENCIAS TÉCNICAS TRANSVERSALES) | O9: ='PLAN CONCERTADO'!O9 -> ( RESULTADOS DE APRENDIZAJE DEL TRIMESTRE ) | W9: ='PLAN CONCERTADO'!W9 -> Presentación del Trimestre: Instructor, Competencias, Resultados, Evidencias, Metodología, Normas y Seguimiento Académico. | AB9: ='PLAN CONCERTADO'!AB9 -> Cronograma de Actividades | AH9: ='PLAN CONCERTADO'!AH9 -> X | AI9: ='PLAN CONCERTADO'!AI9 -> X | AJ9: ='PLAN CONCERTADO'!AJ9 -> X | AK9: ='PLAN CONCERTADO'!AK9 | AL9: ='PLAN CONCERTADO'!AL9 -> X | AM9: ='PLAN CONCERTADO'!AM9 -> 45873 | AO9: ='PLAN CONCERTADO'!AO9 | AP9: ='PLAN CONCERTADO'!AP9 -> X
W10: ='PLAN CONCERTADO'!W10 -> Ajustar el Portafolio del Aprendiz | AB10: ='PLAN CONCERTADO'!AB10 -> Portafolio del Aprendiz con Evidencias de los Trimestres | AH10: ='PLAN CONCERTADO'!AH10 -> X | AI10: ='PLAN CONCERTADO'!AI10 -> X | AJ10: ='PLAN CONCERTADO'!AJ10 -> X | AK10: ='PLAN CONCERTADO'!AK10 | AL10: ='PLAN CONCERTADO'!AL10 -> X | AM10: ='PLAN CONCERTADO'!AM10 -> 45873 | AO10: ='PLAN CONCERTADO'!AO10 | AP10: ='PLAN CONCERTADO'!AP10 -> X
W11: ='PLAN CONCERTADO'!W11 -> Organizar el Sistema Control de Versiones | AB11: ='PLAN CONCERTADO'!AB11 -> Sistema Control Versiones con Entregables Proyecto | AH11: ='PLAN CONCERTADO'!AH11 -> X | AI11: ='PLAN CONCERTADO'!AI11 -> X | AJ11: ='PLAN CONCERTADO'!AJ11 -> X | AK11: ='PLAN CONCERTADO'!AK11 | AL11: ='PLAN CONCERTADO'!AL11 -> X | AM11: ='PLAN CONCERTADO'!AM11 -> 45873 | AO11: ='PLAN CONCERTADO'!AO11 | AP11: ='PLAN CONCERTADO'!AP11 -> X
W12: ='PLAN CONCERTADO'!W12 -> Verificar la calidad de las evidencias del proyecto software de trimestres anteriores | AB12: ='PLAN CONCERTADO'!AB12 -> Evidencias del Proyecto de Trimestres Anteriores | AH12: ='PLAN CONCERTADO'!AH12 -> X | AI12: ='PLAN CONCERTADO'!AI12 -> X | AJ12: ='PLAN CONCERTADO'!AJ12 -> X | AK12: ='PLAN CONCERTADO'!AK12 | AL12: ='PLAN CONCERTADO'!AL12 -> X | AM12: ='PLAN CONCERTADO'!AM12 -> 45873 | AO12: ='PLAN CONCERTADO'!AO12 | AP12: ='PLAN CONCERTADO'!AP12 -> X
G13: ='PLAN CONCERTADO'!G13 -> 220501096 DESARROLLAR LA SOLUCIÓN DE SOFTWARE DE ACUERDO CON EL DISEÑO Y METODOLOGÍAS DE DESARROLLO | O13: ='PLAN CONCERTADO'!O13 -> 220501096_04 CODIFICAR EL SOFTWARE DE ACUERDO CON EL DISEÑO ESTABLECIDO | W13: ='PLAN CONCERTADO'!W13 -> Desarrollar las API REST de la aplicación web | AB13: ='PLAN CONCERTADO'!AB13 -> API REST | AH13: ='PLAN CONCERTADO'!AH13 -> X | AI13: ='PLAN CONCERTADO'!AI13 -> X | AJ13: ='PLAN CONCERTADO'!AJ13 | AK13: ='PLAN CONCERTADO'!AK13 | AL13: ='PLAN CONCERTADO'!AL13 -> X | AM13: ='PLAN CONCERTADO'!AM13 -> 45894 | AO13: ='PLAN CONCERTADO'!AO13 | AP13: ='PLAN CONCERTADO'!AP13 -> X
W14: ='PLAN CONCERTADO'!W14 -> Desarrollo de Frontend de la aplicación web con React, Angular o Vue basado en el diseño web | AB14: ='PLAN CONCERTADO'!AB14 -> Frontend JS | AH14: ='PLAN CONCERTADO'!AH14 -> X | AI14: ='PLAN CONCERTADO'!AI14 -> X | AJ14: ='PLAN CONCERTADO'!AJ14 | AK14: ='PLAN CONCERTADO'!AK14 | AL14: ='PLAN CONCERTADO'!AL14 -> X | AM14: ='PLAN CONCERTADO'!AM14 -> 45894 | AO14: ='PLAN CONCERTADO'!AO14 | AP14: ='PLAN CONCERTADO'!AP14 -> X
W15: ='PLAN CONCERTADO'!W15 -> Incorporar seguridad a la API REST de la aplicación web | AB15: ='PLAN CONCERTADO'!AB15 -> API REST Segura | AH15: ='PLAN CONCERTADO'!AH15 -> X | AI15: ='PLAN CONCERTADO'!AI15 -> X | AJ15: ='PLAN CONCERTADO'!AJ15 | AK15: ='PLAN CONCERTADO'!AK15 | AL15: ='PLAN CONCERTADO'!AL15 -> X | AM15: ='PLAN CONCERTADO'!AM15 -> 45915 | AO15: ='PLAN CONCERTADO'!AO15 | AP15: ='PLAN CONCERTADO'!AP15 -> X
W16: ='PLAN CONCERTADO'!W16 -> Desarrollar la aplicación web | AB16: ='PLAN CONCERTADO'!AB16 -> Aplicación Web (80%) | AH16: ='PLAN CONCERTADO'!AH16 -> X | AI16: ='PLAN CONCERTADO'!AI16 -> X | AJ16: ='PLAN CONCERTADO'!AJ16 | AK16: ='PLAN CONCERTADO'!AK16 | AL16: ='PLAN CONCERTADO'!AL16 -> X | AM16: ='PLAN CONCERTADO'!AM16 -> 45915 | AO16: ='PLAN CONCERTADO'!AO16 | AP16: ='PLAN CONCERTADO'!AP16 -> X
G17: ='PLAN CONCERTADO'!G17 -> ( COMPETENCIAS DEL TRIMESTRE ) | O17: ='PLAN CONCERTADO'!O17 -> ( RESULTADOS DE APRENDIZAJE DEL TRIMESTRE ) | W17: ='PLAN CONCERTADO'!W17 -> EVALUACIÓN DE CONOCIMIENTO | AB17: ='PLAN CONCERTADO'!AB17 -> Presentación Evaluación de Conocimiento | AH17: ='PLAN CONCERTADO'!AH17 -> X | AI17: ='PLAN CONCERTADO'!AI17 | AJ17: ='PLAN CONCERTADO'!AJ17 | AK17: ='PLAN CONCERTADO'!AK17 | AL17: ='PLAN CONCERTADO'!AL17 -> X | AM17: ='PLAN CONCERTADO'!AM17 -> 45915 | AO17: ='PLAN CONCERTADO'!AO17 | AP17: ='PLAN CONCERTADO'!AP17 -> X
W18: ='PLAN CONCERTADO'!W18 -> PRE-SUSTENTACIÓN | AB18: ='PLAN CONCERTADO'!AB18 -> Entregables Proyecto | AH18: ='PLAN CONCERTADO'!AH18 | AI18: ='PLAN CONCERTADO'!AI18 -> X | AJ18: ='PLAN CONCERTADO'!AJ18 | AK18: ='PLAN CONCERTADO'!AK18 | AL18: ='PLAN CONCERTADO'!AL18 -> X | AM18: ='PLAN CONCERTADO'!AM18 -> 45922 | AO18: ='PLAN CONCERTADO'!AO18 | AP18: ='PLAN CONCERTADO'!AP18 -> X
W19: ='PLAN CONCERTADO'!W19 -> SUSTENTACIÓN | AB19: ='PLAN CONCERTADO'!AB19 -> Entregables Proyecto | AH19: ='PLAN CONCERTADO'!AH19 | AI19: ='PLAN CONCERTADO'!AI19 -> X | AJ19: ='PLAN CONCERTADO'!AJ19 | AK19: ='PLAN CONCERTADO'!AK19 | AL19: ='PLAN CONCERTADO'!AL19 -> X | AM19: ='PLAN CONCERTADO'!AM19 -> 45924 | AO19: ='PLAN CONCERTADO'!AO19 | AP19: ='PLAN CONCERTADO'!AP19 -> X
W20: ='PLAN CONCERTADO'!W20 -> AJUSTES PROYECTO Y CIERRE DE TRIMESTRE | AB20: ='PLAN CONCERTADO'!AB20 -> Ajuste de los entregables del Proyecto | AH20: ='PLAN CONCERTADO'!AH20 | AI20: ='PLAN CONCERTADO'!AI20 -> X | AJ20: ='PLAN CONCERTADO'!AJ20 | AK20: ='PLAN CONCERTADO'!AK20 | AL20: ='PLAN CONCERTADO'!AL20 -> X | AM20: ='PLAN CONCERTADO'!AM20 -> 45936 | AO20: ='PLAN CONCERTADO'!AO20 | AP20: ='PLAN CONCERTADO'!AP20 -> X

Sheet 2
A1: FORMATO PLAN CONCERTADO DE LA RUTA DE APRENDIZAJE
A2: Instructor | D2: EDWIN ALBEIRO RAMOS VILLAMIL | P2: Trimestre del año | T2: III
A3: Programa de Formación | F3: ANÁLISIS Y DESARROLLO DE SOFTWARE | P3: Trimestre Formación | T3: V
A4: Nivel | C4: TECNÓLOGO | E4: Ficha | G4: 2996150 | J4: Jornada | M4: DIURNA | P4: Fecha Concertación | T4: 45866
A7: Aprendiz | G7: Competencia | O7: Resultado de Aprendizaje | W7: Temática | AB7: Evidencia de Aprendizaje | AH7: Tipo de Evidencia | AK7: Formato de Entrega | AM7: Fecha de Entrega | AO7: Entregó
AH8: EC | AI8: ED | AJ8: EP | AK8: Físico | AL8: Digital | AO8: Sí | AP8: No
A9: ='PLAN CONCERTADO'!B10 -> DANIELA LORENA BOHORQUEZ DIAZ | G9: ='PLAN CONCERTADO'!G9 -> ( COMPETENCIAS TÉCNICAS TRANSVERSALES) | O9: ='PLAN CONCERTADO'!O9 -> ( RESULTADOS DE APRENDIZAJE DEL TRIMESTRE ) | W9: ='PLAN CONCERTADO'!W9 -> Presentación del Trimestre: Instructor, Competencias, Resultados, Evidencias, Metodología, Normas y Seguimiento Académico. | AB9: ='PLAN CONCERTADO'!AB9 -> Cronograma de Actividades | AH9: ='PLAN CONCERTADO'!AH9 -> X | AI9: ='PLAN CONCERTADO'!AI9 -> X | AJ9: ='PLAN CONCERTADO'!AJ9 -> X | AK9: ='PLAN CONCERTADO'!AK9 | AL9: ='PLAN CONCERTADO'!AL9 -> X | AM9: ='PLAN CONCERTADO'!AM9 -> 45873 | AO9: ='PLAN CONCERTADO'!AO9 | AP9: ='PLAN CONCERTADO'!AP9 -> X
W10: ='PLAN CONCERTADO'!W10 -> Ajustar el Portafolio del Aprendiz | AB10: ='PLAN CONCERTADO'!AB10 -> Portafolio del Aprendiz con Evidencias de los Trimestres | AH10: ='PLAN CONCERTADO'!AH10 -> X | AI10: ='PLAN CONCERTADO'!AI10 -> X | AJ10: ='PLAN CONCERTADO'!AJ10 -> X | AK10: ='PLAN CONCERTADO'!AK10 | AL10: ='PLAN CONCERTADO'!AL10 -> X | AM10: ='PLAN CONCERTADO'!AM10 -> 45873 | AO10: ='PLAN CONCERTADO'!AO10 | AP10: ='PLAN CONCERTADO'!AP10 -> X
W11: ='PLAN CONCERTADO'!W11 -> Organizar el Sistema Control de Versiones | AB11: ='PLAN CONCERTADO'!AB11 -> Sistema Control Versiones con Entregables Proyecto | AH11: ='PLAN CONCERTADO'!AH11 -> X | AI11: ='PLAN CONCERTADO'!AI11 -> X | AJ11: ='PLAN CONCERTADO'!AJ11 -> X | AK11: ='PLAN CONCERTADO'!AK11 | AL11: ='PLAN CONCERTADO'!AL11 -> X | AM11: ='PLAN CONCERTADO'!AM11 -> 45873 | AO11: ='PLAN CONCERTADO'!AO11 | AP11: ='PLAN CONCERTADO'!AP11 -> X
W12: ='PLAN CONCERTADO'!W12 -> Verificar la calidad de las evidencias del proyecto software de trimestres anteriores | AB12: ='PLAN CONCERTADO'!AB12 -> Evidencias del Proyecto de Trimestres Anteriores | AH12: ='PLAN CONCERTADO'!AH12 -> X | AI12: ='PLAN CONCERTADO'!AI12 -> X | AJ12: ='PLAN CONCERTADO'!AJ12 -> X | AK12: ='PLAN CONCERTADO'!AK12 | AL12: ='PLAN CONCERTADO'!AL12 -> X | AM12: ='PLAN CONCERTADO'!AM12 -> 45873 | AO12: ='PLAN CONCERTADO'!AO12 | AP12: ='PLAN CONCERTADO'!AP12 -> X
G13: ='PLAN CONCERTADO'!G13 -> 220501096 DESARROLLAR LA SOLUCIÓN DE SOFTWARE DE ACUERDO CON EL DISEÑO Y METODOLOGÍAS DE DESARROLLO | O13: ='PLAN CONCERTADO'!O13 -> 220501096_04 CODIFICAR EL SOFTWARE DE ACUERDO CON EL DISEÑO ESTABLECIDO | W13: ='PLAN CONCERTADO'!W13 -> Desarrollar las API REST de la aplicación web | AB13: ='PLAN CONCERTADO'!AB13 -> API REST | AH13: ='PLAN CONCERTADO'!AH13 -> X | AI13: ='PLAN CONCERTADO'!AI13 -> X | AJ13: ='PLAN CONCERTADO'!AJ13 | AK13: ='PLAN CONCERTADO'!AK13 | AL13: ='PLAN CONCERTADO'!AL13 -> X | AM13: ='PLAN CONCERTADO'!AM13 -> 45894 | AO13: ='PLAN CONCERTADO'!AO13 | AP13: ='PLAN CONCERTADO'!AP13 -> X
W14: ='PLAN CONCERTADO'!W14 -> Desarrollo de Frontend de la aplicación web con React, Angular o Vue basado en el diseño web | AB14: ='PLAN CONCERTADO'!AB14 -> Frontend JS | AH14: ='PLAN CONCERTADO'!AH14 -> X | AI14: ='PLAN CONCERTADO'!AI14 -> X | AJ14: ='PLAN CONCERTADO'!AJ14 | AK14: ='PLAN CONCERTADO'!AK14 | AL14: ='PLAN CONCERTADO'!AL14 -> X | AM14: ='PLAN CONCERTADO'!AM14 -> 45894 | AO14: ='PLAN CONCERTADO'!AO14 | AP14: ='PLAN CONCERTADO'!AP14 -> X
W15: ='PLAN CONCERTADO'!W15 -> Incorporar seguridad a la API REST de la aplicación web | AB15: ='PLAN CONCERTADO'!AB15 -> API REST Segura | AH15: ='PLAN CONCERTADO'!AH15 -> X | AI15: ='PLAN CONCERTADO'!AI15 -> X | AJ15: ='PLAN CONCERTADO'!AJ15 | AK15: ='PLAN CONCERTADO'!AK15 | AL15: ='PLAN CONCERTADO'!AL15 -> X | AM15: ='PLAN CONCERTADO'!AM15 -> 45915 | AO15: ='PLAN CONCERTADO'!AO15 | AP15: ='PLAN CONCERTADO'!AP15 -> X
W16: ='PLAN CONCERTADO'!W16 -> Desarrollar la aplicación web | AB16: ='PLAN CONCERTADO'!AB16 -> Aplicación Web (80%) | AH16: ='PLAN CONCERTADO'!AH16 -> X | AI16: ='PLAN CONCERTADO'!AI16 -> X | AJ16: ='PLAN CONCERTADO'!AJ16 | AK16: ='PLAN CONCERTADO'!AK16 | AL16: ='PLAN CONCERTADO'!AL16 -> X | AM16: ='PLAN CONCERTADO'!AM16 -> 45915 | AO16: ='PLAN CONCERTADO'!AO16 | AP16: ='PLAN CONCERTADO'!AP16 -> X
G17: ='PLAN CONCERTADO'!G17 -> ( COMPETENCIAS DEL TRIMESTRE ) | O17: ='PLAN CONCERTADO'!O17 -> ( RESULTADOS DE APRENDIZAJE DEL TRIMESTRE ) | W17: ='PLAN CONCERTADO'!W17 -> EVALUACIÓN DE CONOCIMIENTO | AB17: ='PLAN CONCERTADO'!AB17 -> Presentación Evaluación de Conocimiento | AH17: ='PLAN CONCERTADO'!AH17 -> X | AI17: ='PLAN CONCERTADO'!AI17 | AJ17: ='PLAN CONCERTADO'!AJ17 | AK17: ='PLAN CONCERTADO'!AK17 | AL17: ='PLAN CONCERTADO'!AL17 -> X | AM17: ='PLAN CONCERTADO'!AM17 -> 45915 | AO17: ='PLAN CONCERTADO'!AO17 | AP17: ='PLAN CONCERTADO'!AP17 -> X
W18: ='PLAN CONCERTADO'!W18 -> PRE-SUSTENTACIÓN | AB18: ='PLAN CONCERTADO'!AB18 -> Entregables Proyecto | AH18: ='PLAN CONCERTADO'!AH18 | AI18: ='PLAN CONCERTADO'!AI18 -> X | AJ18: ='PLAN CONCERTADO'!AJ18 | AK18: ='PLAN CONCERTADO'!AK18 | AL18: ='PLAN CONCERTADO'!AL18 -> X | AM18: ='PLAN CONCERTADO'!AM18 -> 45922 | AO18: ='PLAN CONCERTADO'!AO18 | AP18: ='PLAN CONCERTADO'!AP18 -> X
W19: ='PLAN CONCERTADO'!W19 -> SUSTENTACIÓN | AB19: ='PLAN CONCERTADO'!AB19 -> Entregables Proyecto | AH19: ='PLAN CONCERTADO'!AH19 | AI19: ='PLAN CONCERTADO'!AI19 -> X | AJ19: ='PLAN CONCERTADO'!AJ19 | AK19: ='PLAN CONCERTADO'!AK19 | AL19: ='PLAN CONCERTADO'!AL19 -> X | AM19: ='PLAN CONCERTADO'!AM19 -> 45924 | AO19: ='PLAN CONCERTADO'!AO19 | AP19: ='PLAN CONCERTADO'!AP19 -> X
W20: ='PLAN CONCERTADO'!W20 -> AJUSTES PROYECTO Y CIERRE DE TRIMESTRE | AB20: ='PLAN CONCERTADO'!AB20 -> Ajuste de los entregables del Proyecto | AH20: ='PLAN CONCERTADO'!AH20 | AI20: ='PLAN CONCERTADO'!AI20 -> X | AJ20: ='PLAN CONCERTADO'!AJ20 | AK20: ='PLAN CONCERTADO'!AK20 | AL20: ='PLAN CONCERTADO'!AL20 -> X | AM20: ='PLAN CONCERTADO'!AM20 -> 45936 | AO20: ='PLAN CONCERTADO'!AO20 | AP20: ='PLAN CONCERTADO'!AP20 -> X

Sheet 3
A1: FORMATO PLAN CONCERTADO DE LA RUTA DE APRENDIZAJE
A2: Instructor | D2: EDWIN ALBEIRO RAMOS VILLAMIL | P2: Trimestre del año | T2: III
A3: Programa de Formación | F3: ANÁLISIS Y DESARROLLO DE SOFTWARE | P3: Trimestre Formación | T3: V
A4: Nivel | C4: TECNÓLOGO | E4: Ficha | G4: 2996150 | J4: Jornada | M4: DIURNA | P4: Fecha Concertación | T4: 45866
A7: Aprendiz | G7: Competencia | O7: Resultado de Aprendizaje | W7: Temática | AB7: Evidencia de Aprendizaje | AH7: Tipo de Evidencia | AK7: Formato de Entrega | AM7: Fecha de Entrega | AO7: Entregó
AH8: EC | AI8: ED | AJ8: EP | AK8: Físico | AL8: Digital | AO8: Sí | AP8: No
A9: ='PLAN CONCERTADO'!B11 -> JHONATAN CARVAJAL BONILLA | G9: ='PLAN CONCERTADO'!G9 -> ( COMPETENCIAS TÉCNICAS TRANSVERSALES) | O9: ='PLAN CONCERTADO'!O9 -> ( RESULTADOS DE APRENDIZAJE DEL TRIMESTRE ) | W9: ='PLAN CONCERTADO'!W9 -> Presentación del Trimestre: Instructor, Competencias, Resultados, Evidencias, Metodología, Normas y Seguimiento Académico. | AB9: ='PLAN CONCERTADO'!AB9 -> Cronograma de Actividades | AH9: ='PLAN CONCERTADO'!AH9 -> X | AI9: ='PLAN CONCERTADO'!AI9 -> X | AJ9: ='PLAN CONCERTADO'!AJ9 -> X | AK9: ='PLAN CONCERTADO'!AK9 | AL9: ='PLAN CONCERTADO'!AL9 -> X | AM9: ='PLAN CONCERTADO'!AM9 -> 45873 | AO9: ='PLAN CONCERTADO'!AO9 | AP9: ='PLAN CONCERTADO'!AP9 -> X
W10: ='PLAN CONCERTADO'!W10 -> Ajustar el Portafolio del Aprendiz | AB10: ='PLAN CONCERTADO'!AB10 -> Portafolio del Aprendiz con Evidencias de los Trimestres | AH10: ='PLAN CONCERTADO'!AH10 -> X | AI10: ='PLAN CONCERTADO'!AI10 -> X | AJ10: ='PLAN CONCERTADO'!AJ10 -> X | AK10: ='PLAN CONCERTADO'!AK10 | AL10: ='PLAN CONCERTADO'!AL10 -> X | AM10: ='PLAN CONCERTADO'!AM10 -> 45873 | AO10: ='PLAN CONCERTADO'!AO10 | AP10: ='PLAN CONCERTADO'!AP10 -> X
W11: ='PLAN CONCERTADO'!W11 -> Organizar el Sistema Control de Versiones | AB11: ='PLAN CONCERTADO'!AB11 -> Sistema Control Versiones con Entregables Proyecto | AH11: ='PLAN CONCERTADO'!AH11 -> X | AI11: ='PLAN CONCERTADO'!AI11 -> X | AJ11: ='PLAN CONCERTADO'!AJ11 -> X | AK11: ='PLAN CONCERTADO'!AK11 | AL11: ='PLAN CONCERTADO'!AL11 -> X | AM11: ='PLAN CONCERTADO'!AM11 -> 45873 | AO11: ='PLAN CONCERTADO'!AO11 | AP11: ='PLAN CONCERTADO'!AP11 -> X
W12: ='PLAN CONCERTADO'!W12 -> Verificar la calidad de las evidencias del proyecto software de trimestres anteriores | AB12: ='PLAN CONCERTADO'!AB12 -> Evidencias del Proyecto de Trimestres Anteriores | AH12: ='PLAN CONCERTADO'!AH12 -> X | AI12: ='PLAN CONCERTADO'!AI12 -> X | AJ12: ='PLAN CONCERTADO'!AJ12 -> X | AK12: ='PLAN CONCERTADO'!AK12 | AL12: ='PLAN CONCERTADO'!AL12 -> X | AM12: ='PLAN CONCERTADO'!AM12 -> 45873 | AO12: ='PLAN CONCERTADO'!AO12 | AP12: ='PLAN CONCERTADO'!AP12 -> X
G13: ='PLAN CONCERTADO'!G13 -> 220501096 DESARROLLAR LA SOLUCIÓN DE SOFTWARE DE ACUERDO CON EL DISEÑO Y METODOLOGÍAS DE DESARROLLO | O13: ='PLAN CONCERTADO'!O13 -> 220501096_04 CODIFICAR EL SOFTWARE DE ACUERDO CON EL DISEÑO ESTABLECIDO | W13: ='PLAN CONCERTADO'!W13 -> Desarrollar las API REST de la aplicación web | AB13: ='PLAN CONCERTADO'!AB13 -> API REST | AH13: ='PLAN CONCERTADO'!AH13 -> X | AI13: ='PLAN CONCERTADO'!AI13 -> X | AJ13: ='PLAN CONCERTADO'!AJ13 | AK13: ='PLAN CONCERTADO'!AK13 | AL13: ='PLAN CONCERTADO'!AL13 -> X | AM13: ='PLAN CONCERTADO'!AM13 -> 45894 | AO13: ='PLAN CONCERTADO'!AO13 | AP13: ='PLAN CONCERTADO'!AP13 -> X
W14: ='PLAN CONCERTADO'!W14 -> Desarrollo de Frontend de la aplicación web con React, Angular o Vue basado en el diseño web | AB14: ='PLAN CONCERTADO'!AB14 -> Frontend JS | AH14: ='PLAN CONCERTADO'!AH14 -> X | AI14: ='PLAN CONCERTADO'!AI14 -> X | AJ14: ='PLAN CONCERTADO'!AJ14 | AK14: ='PLAN CONCERTADO'!AK14 | AL14: ='PLAN CONCERTADO'!AL14 -> X | AM14: ='PLAN CONCERTADO'!AM14 -> 45894 | AO14: ='PLAN CONCERTADO'!AO14 | AP14: ='PLAN CONCERTADO'!AP14 -> X
W15: ='PLAN CONCERTADO'!W15 -> Incorporar seguridad a la API REST de la aplicación web | AB15: ='PLAN CONCERTADO'!AB15 -> API REST Segura | AH15: ='PLAN CONCERTADO'!AH15 -> X | AI15: ='PLAN CONCERTADO'!AI15 -> X | AJ15: ='PLAN CONCERTADO'!AJ15 | AK15: ='PLAN CONCERTADO'!AK15 | AL15: ='PLAN CONCERTADO'!AL15 -> X | AM15: ='PLAN CONCERTADO'!AM15 -> 45915 | AO15: ='PLAN CONCERTADO'!AO15 | AP15: ='PLAN CONCERTADO'!AP15 -> X
W16: ='PLAN CONCERTADO'!W16 -> Desarrollar la aplicación web | AB16: ='PLAN CONCERTADO'!AB16 -> Aplicación Web (80%) | AH16: ='PLAN CONCERTADO'!AH16 -> X | AI16: ='PLAN CONCERTADO'!AI16 -> X | AJ16: ='PLAN CONCERTADO'!AJ16 | AK16: ='PLAN CONCERTADO'!AK16 | AL16: ='PLAN CONCERTADO'!AL16 -> X | AM16: ='PLAN CONCERTADO'!AM16 -> 45915 | AO16: ='PLAN CONCERTADO'!AO16 | AP16: ='PLAN CONCERTADO'!AP16 -> X
G17: ='PLAN CONCERTADO'!G17 -> ( COMPETENCIAS DEL TRIMESTRE ) | O17: ='PLAN CONCERTADO'!O17 -> ( RESULTADOS DE APRENDIZAJE DEL TRIMESTRE ) | W17: ='PLAN CONCERTADO'!W17 -> EVALUACIÓN DE CONOCIMIENTO | AB17: ='PLAN CONCERTADO'!AB17 -> Presentación Evaluación de Conocimiento | AH17: ='PLAN CONCERTADO'!AH17 -> X | AI17: ='PLAN CONCERTADO'!AI17 | AJ17: ='PLAN CONCERTADO'!AJ17 | AK17: ='PLAN CONCERTADO'!AK17 | AL17: ='PLAN CONCERTADO'!AL17 -> X | AM17: ='PLAN CONCERTADO'!AM17 -> 45915 | AO17: ='PLAN CONCERTADO'!AO17 | AP17: ='PLAN CONCERTADO'!AP17 -> X
W18: ='PLAN CONCERTADO'!W18 -> PRE-SUSTENTACIÓN | AB18: ='PLAN CONCERTADO'!AB18 -> Entregables Proyecto | AH18: ='PLAN CONCERTADO'!AH18 | AI18: ='PLAN CONCERTADO'!AI18 -> X | AJ18: ='PLAN CONCERTADO'!AJ18 | AK18: ='PLAN CONCERTADO'!AK18 | AL18: ='PLAN CONCERTADO'!AL18 -> X | AM18: ='PLAN CONCERTADO'!AM18 -> 45922 | AO18: ='PLAN CONCERTADO'!AO18 | AP18: ='PLAN CONCERTADO'!AP18 -> X
W19: ='PLAN CONCERTADO'!W19 -> SUSTENTACIÓN | AB19: ='PLAN CONCERTADO'!AB19 -> Entregables Proyecto | AH19: ='PLAN CONCERTADO'!AH19 | AI19: ='PLAN CONCERTADO'!AI19 -> X | AJ19: ='PLAN CONCERTADO'!AJ19 | AK19: ='PLAN CONCERTADO'!AK19 | AL19: ='PLAN CONCERTADO'!AL19 -> X | AM19: ='PLAN CONCERTADO'!AM19 -> 45924 | AO19: ='PLAN CONCERTADO'!AO19 | AP19: ='PLAN CONCERTADO'!AP19 -> X
W20: ='PLAN CONCERTADO'!W20 -> AJUSTES PROYECTO Y CIERRE DE TRIMESTRE | AB20: ='PLAN CONCERTADO'!AB20 -> Ajuste de los entregables del Proyecto | AH20: ='PLAN CONCERTADO'!AH20 | AI20: ='PLAN CONCERTADO'!AI20 -> X | AJ20: ='PLAN CONCERTADO'!AJ20 | AK20: ='PLAN CONCERTADO'!AK20 | AL20: ='PLAN CONCERTADO'!AL20 -> X | AM20: ='PLAN CONCERTADO'!AM20 -> 45936 | AO20: ='PLAN CONCERTADO'!AO20 | AP20: ='PLAN CONCERTADO'!AP20 -> X

Sheet 4
A1: FORMATO PLAN CONCERTADO DE LA RUTA DE APRENDIZAJE
A2: Instructor | D2: EDWIN ALBEIRO RAMOS VILLAMIL | P2: Trimestre del año | T2: III
A3: Programa de Formación | F3: ANÁLISIS Y DESARROLLO DE SOFTWARE | P3: Trimestre Formación | T3: V
A4: Nivel | C4: TECNÓLOGO | E4: Ficha | G4: 2996150 | J4: Jornada | M4: DIURNA | P4: Fecha Concertación | T4: 45866
A7: Aprendiz | G7: Competencia | O7: Resultado de Aprendizaje | W7: Temática | AB7: Evidencia de Aprendizaje | AH7: Tipo de Evidencia | AK7: Formato de Entrega | AM7: Fecha de Entrega | AO7: Entregó
AH8: EC | AI8: ED | AJ8: EP | AK8: Físico | AL8: Digital | AO8: Sí | AP8: No
A9: ='PLAN CONCERTADO'!B12 -> PAULA ANDREA CASSIANI CASTILLO | G9: ='PLAN CONCERTADO'!G9 -> ( COMPETENCIAS TÉCNICAS TRANSVERSALES) | O9: ='PLAN CONCERTADO'!O9 -> ( RESULTADOS DE APRENDIZAJE DEL TRIMESTRE ) | W9: ='PLAN CONCERTADO'!W9 -> Presentación del Trimestre: Instructor, Competencias, Resultados, Evidencias, Metodología, Normas y Seguimiento Académico. | AB9: ='PLAN CONCERTADO'!AB9 -> Cronograma de Actividades | AH9: ='PLAN CONCERTADO'!AH9 -> X | AI9: ='PLAN CONCERTADO'!AI9 -> X | AJ9: ='PLAN CONCERTADO'!AJ9 -> X | AK9: ='PLAN CONCERTADO'!AK9 | AL9: ='PLAN CONCERTADO'!AL9 -> X | AM9: ='PLAN CONCERTADO'!AM9 -> 45873 | AO9: ='PLAN CONCERTADO'!AO9 | AP9: ='PLAN CONCERTADO'!AP9 -> X
W10: ='PLAN CONCERTADO'!W10 -> Ajustar el Portafolio del Aprendiz | AB10: ='PLAN CONCERTADO'!AB10 -> Portafolio del Aprendiz con Evidencias de los Trimestres | AH10: ='PLAN CONCERTADO'!AH10 -> X | AI10: ='PLAN CONCERTADO'!AI10 -> X | AJ10: ='PLAN CONCERTADO'!AJ10 -> X | AK10: ='PLAN CONCERTADO'!AK10 | AL10: ='PLAN CONCERTADO'!AL10 -> X | AM10: ='PLAN CONCERTADO'!AM10 -> 45873 | AO10: ='PLAN CONCERTADO'!AO10 | AP10: ='PLAN CONCERTADO'!AP10 -> X
W11: ='PLAN CONCERTADO'!W11 -> Organizar el Sistema Control de Versiones | AB11: ='PLAN CONCERTADO'!AB11 -> Sistema Control Versiones con Entregables Proyecto | AH11: ='PLAN CONCERTADO'!AH11 -> X | AI11: ='PLAN CONCERTADO'!AI11 -> X | AJ11: ='PLAN CONCERTADO'!AJ11 -> X | AK11: ='PLAN CONCERTADO'!AK11 | AL11: ='PLAN CONCERTADO'!AL11 -> X | AM11: ='PLAN CONCERTADO'!AM11 -> 45873 | AO11: ='PLAN CONCERTADO'!AO11 | AP11: ='PLAN CONCERTADO'!AP11 -> X
W12: ='PLAN CONCERTADO'!W12 -> Verificar la calidad de las evidencias del proyecto software de trimestres anteriores | AB12: ='PLAN CONCERTADO'!AB12 -> Evidencias del Proyecto de Trimestres Anteriores | AH12: ='PLAN CONCERTADO'!AH12 -> X | AI12: ='PLAN CONCERTADO'!AI12 -> X | AJ12: ='PLAN CONCERTADO'!AJ12 -> X | AK12: ='PLAN CONCERTADO'!AK12 | AL12: ='PLAN CONCERTADO'!AL12 -> X | AM12: ='PLAN CONCERTADO'!AM12 -> 45873 | AO12: ='PLAN CONCERTADO'!AO12 | AP12: ='PLAN CONCERTADO'!AP12 -> X
G13: ='PLAN CONCERTADO'!G13 -> 220501096 DESARROLLAR LA SOLUCIÓN DE SOFTWARE DE ACUERDO CON EL DISEÑO Y METODOLOGÍAS DE DESARROLLO | O13: ='PLAN CONCERTADO'!O13 -> 220501096_04 CODIFICAR EL SOFTWARE DE ACUERDO CON EL DISEÑO ESTABLECIDO | W13: ='PLAN CONCERTADO'!W13 -> Desarrollar las API REST de la aplicación web | AB13: ='PLAN CONCERTADO'!AB13 -> API REST | AH13: ='PLAN CONCERTADO'!AH13 -> X | AI13: ='PLAN CONCERTADO'!AI13 -> X | AJ13: ='PLAN CONCERTADO'!AJ13 | AK13: ='PLAN CONCERTADO'!AK13 | AL13: ='PLAN CONCERTADO'!AL13 -> X | AM13: ='PLAN CONCERTADO'!AM13 -> 45894 | AO13: ='PLAN CONCERTADO'!AO13 | AP13: ='PLAN CONCERTADO'!AP13 -> X
W14: ='PLAN CONCERTADO'!W14 -> Desarrollo de Frontend de la aplicación web con React, Angular o Vue basado en el diseño web | AB14: ='PLAN CONCERTADO'!AB14 -> Frontend JS | AH14: ='PLAN CONCERTADO'!AH14 -> X | AI14: ='PLAN CONCERTADO'!AI14 -> X | AJ14: ='PLAN CONCERTADO'!AJ14 | AK14: ='PLAN CONCERTADO'!AK14 | AL14: ='PLAN CONCERTADO'!AL14 -> X | AM14: ='PLAN CONCERTADO'!AM14 -> 45894 | AO14: ='PLAN CONCERTADO'!AO14 | AP14: ='PLAN CONCERTADO'!AP14 -> X
W15: ='PLAN CONCERTADO'!W15 -> Incorporar seguridad a la API REST de la aplicación web | AB15: ='PLAN CONCERTADO'!AB15 -> API REST Segura | AH15: ='PLAN CONCERTADO'!AH15 -> X | AI15: ='PLAN CONCERTADO'!AI15 -> X | AJ15: ='PLAN CONCERTADO'!AJ15 | AK15: ='PLAN CONCERTADO'!AK15 | AL15: ='PLAN CONCERTADO'!AL15 -> X | AM15: ='PLAN CONCERTADO'!AM15 -> 45915 | AO15: ='PLAN CONCERTADO'!AO15 | AP15: ='PLAN CONCERTADO'!AP15 -> X
W16: ='PLAN CONCERTADO'!W16 -> Desarrollar la aplicación web | AB16: ='PLAN CONCERTADO'!AB16 -> Aplicación Web (80%) | AH16: ='PLAN CONCERTADO'!AH16 -> X | AI16: ='PLAN CONCERTADO'!AI16 -> X | AJ16: ='PLAN CONCERTADO'!AJ16 | AK16: ='PLAN CONCERTADO'!AK16 | AL16: ='PLAN CONCERTADO'!AL16 -> X | AM16: ='PLAN CONCERTADO'!AM16 -> 45915 | AO16: ='PLAN CONCERTADO'!AO16 | AP16: ='PLAN CONCERTADO'!AP16 -> X
G17: ='PLAN CONCERTADO'!G17 -> ( COMPETENCIAS DEL TRIMESTRE ) | O17: ='PLAN CONCERTADO'!O17 -> ( RESULTADOS DE APRENDIZAJE DEL TRIMESTRE ) | W17: ='PLAN CONCERTADO'!W17 -> EVALUACIÓN DE CONOCIMIENTO | AB17: ='PLAN CONCERTADO'!AB17 -> Presentación Evaluación de Conocimiento | AH17: ='PLAN CONCERTADO'!AH17 -> X | AI17: ='PLAN CONCERTADO'!AI17 | AJ17: ='PLAN CONCERTADO'!AJ17 | AK17: ='PLAN CONCERTADO'!AK17 | AL17: ='PLAN CONCERTADO'!AL17 -> X | AM17: ='PLAN CONCERTADO'!AM17 -> 45915 | AO17: ='PLAN CONCERTADO'!AO17 | AP17: ='PLAN CONCERTADO'!AP17 -> X
W18: ='PLAN CONCERTADO'!W18 -> PRE-SUSTENTACIÓN | AB18: ='PLAN CONCERTADO'!AB18 -> Entregables Proyecto | AH18: ='PLAN CONCERTADO'!AH18 | AI18: ='PLAN CONCERTADO'!AI18 -> X | AJ18: ='PLAN CONCERTADO'!AJ18 | AK18: ='PLAN CONCERTADO'!AK18 | AL18: ='PLAN CONCERTADO'!AL18 -> X | AM18: ='PLAN CONCERTADO'!AM18 -> 45922 | AO18: ='PLAN CONCERTADO'!AO18 | AP18: ='PLAN CONCERTADO'!AP18 -> X
W19: ='PLAN CONCERTADO'!W19 -> SUSTENTACIÓN | AB19: ='PLAN CONCERTADO'!AB19 -> Entregables Proyecto | AH19: ='PLAN CONCERTADO'!AH19 | AI19: ='PLAN CONCERTADO'!AI19 -> X | AJ19: ='PLAN CONCERTADO'!AJ19 | AK19: ='PLAN CONCERTADO'!AK19 | AL19: ='PLAN CONCERTADO'!AL19 -> X | AM19: ='PLAN CONCERTADO'!AM19 -> 45924 | AO19: ='PLAN CONCERTADO'!AO19 | AP19: ='PLAN CONCERTADO'!AP19 -> X
W20: ='PLAN CONCERTADO'!W20 -> AJUSTES PROYECTO Y CIERRE DE TRIMESTRE | AB20: ='PLAN CONCERTADO'!AB20 -> Ajuste de los entregables del Proyecto | AH20: ='PLAN CONCERTADO'!AH20 | AI20: ='PLAN CONCERTADO'!AI20 -> X | AJ20: ='PLAN CONCERTADO'!AJ20 | AK20: ='PLAN CONCERTADO'!AK20 | AL20: ='PLAN CONCERTADO'!AL20 -> X | AM20: ='PLAN CONCERTADO'!AM20 -> 45936 | AO20: ='PLAN CONCERTADO'!AO20 | AP20: ='PLAN CONCERTADO'!AP20 -> X

Sheet 5
A1: FORMATO PLAN CONCERTADO DE LA RUTA DE APRENDIZAJE
A2: Instructor | D2: EDWIN ALBEIRO RAMOS VILLAMIL | P2: Trimestre del año | T2: III
A3: Programa de Formación | F3: ANÁLISIS Y DESARROLLO DE SOFTWARE | P3: Trimestre Formación | T3: V
A4: Nivel | C4: TECNÓLOGO | E4: Ficha | G4: 2996150 | J4: Jornada | M4: DIURNA | P4: Fecha Concertación | T4: 45866
A7: Aprendiz | G7: Competencia | O7: Resultado de Aprendizaje | W7: Temática | AB7: Evidencia de Aprendizaje | AH7: Tipo de Evidencia | AK7: Formato de Entrega | AM7: Fecha de Entrega | AO7: Entregó
AH8: EC | AI8: ED | AJ8: EP | AK8: Físico | AL8: Digital | AO8: Sí | AP8: No
A9: ='PLAN CONCERTADO'!B13 -> DANIEL CASTILLO MORA | G9: ='PLAN CONCERTADO'!G9 -> ( COMPETENCIAS TÉCNICAS TRANSVERSALES) | O9: ='PLAN CONCERTADO'!O9 -> ( RESULTADOS DE APRENDIZAJE DEL TRIMESTRE ) | W9: ='PLAN CONCERTADO'!W9 -> Presentación del Trimestre: Instructor, Competencias, Resultados, Evidencias, Metodología, Normas y Seguimiento Académico. | AB9: ='PLAN CONCERTADO'!AB9 -> Cronograma de Actividades | AH9: ='PLAN CONCERTADO'!AH9 -> X | AI9: ='PLAN CONCERTADO'!AI9 -> X | AJ9: ='PLAN CONCERTADO'!AJ9 -> X | AK9: ='PLAN CONCERTADO'!AK9 | AL9: ='PLAN CONCERTADO'!AL9 -> X | AM9: ='PLAN CONCERTADO'!AM9 -> 45873 | AO9: ='PLAN CONCERTADO'!AO9 | AP9: ='PLAN CONCERTADO'!AP9 -> X
W10: ='PLAN CONCERTADO'!W10 -> Ajustar el Portafolio del Aprendiz | AB10: ='PLAN CONCERTADO'!AB10 -> Portafolio del Aprendiz con Evidencias de los Trimestres | AH10: ='PLAN CONCERTADO'!AH10 -> X | AI10: ='PLAN CONCERTADO'!AI10 -> X | AJ10: ='PLAN CONCERTADO'!AJ10 -> X | AK10: ='PLAN CONCERTADO'!AK10 | AL10: ='PLAN CONCERTADO'!AL10 -> X | AM10: ='PLAN CONCERTADO'!AM10 -> 45873 | AO10: ='PLAN CONCERTADO'!AO10 | AP10: ='PLAN CONCERTADO'!AP10 -> X
W11: ='PLAN CONCERTADO'!W11 -> Organizar el Sistema Control de Versiones | AB11: ='PLAN CONCERTADO'!AB11 -> Sistema Control Versiones con Entregables Proyecto | AH11: ='PLAN CONCERTADO'!AH11 -> X | AI11: ='PLAN CONCERTADO'!AI11 -> X | AJ11: ='PLAN CONCERTADO'!AJ11 -> X | AK11: ='PLAN CONCERTADO'!AK11 | AL11: ='PLAN CONCERTADO'!AL11 -> X | AM11: ='PLAN CONCERTADO'!AM11 -> 45873 | AO11: ='PLAN CONCERTADO'!AO11 | AP11: ='PLAN CONCERTADO'!AP11 -> X
W12: ='PLAN CONCERTADO'!W12 -> Verificar la calidad de las evidencias del proyecto software de trimestres anteriores | AB12: ='PLAN CONCERTADO'!AB12 -> Evidencias del Proyecto de Trimestres Anteriores | AH12: ='PLAN CONCERTADO'!AH12 -> X | AI12: ='PLAN CONCERTADO'!AI12 -> X | AJ12: ='PLAN CONCERTADO'!AJ12 -> X | AK12: ='PLAN CONCERTADO'!AK12 | AL12: ='PLAN CONCERTADO'!AL12 -> X | AM12: ='PLAN CONCERTADO'!AM12 -> 45873 | AO12: ='PLAN CONCERTADO'!AO12 | AP12: ='PLAN CONCERTADO'!AP12 -> X
G13: ='PLAN CONCERTADO'!G13 -> 220501096 DESARROLLAR LA SOLUCIÓN DE SOFTWARE DE ACUERDO CON EL DISEÑO Y METODOLOGÍAS DE DESARROLLO | O13: ='PLAN CONCERTADO'!O13 -> 220501096_04 CODIFICAR EL SOFTWARE DE ACUERDO CON EL DISEÑO ESTABLECIDO | W13: ='PLAN CONCERTADO'!W13 -> Desarrollar las API REST de la aplicación web | AB13: ='PLAN CONCERTADO'!AB13 -> API REST | AH13: ='PLAN CONCERTADO'!AH13 -> X | AI13: ='PLAN CONCERTADO'!AI13 -> X | AJ13: ='PLAN CONCERTADO'!AJ13 | AK13: ='PLAN CONCERTADO'!AK13 | AL13: ='PLAN CONCERTADO'!AL13 -> X | AM13: ='PLAN CONCERTADO'!AM13 -> 45894 | AO13: ='PLAN CONCERTADO'!AO13 | AP13: ='PLAN CONCERTADO'!AP13 -> X
W14: ='PLAN CONCERTADO'!W14 -> Desarrollo de Frontend de la aplicación web con React, Angular o Vue basado en el diseño web | AB14: ='PLAN CONCERTADO'!AB14 -> Frontend JS | AH14: ='PLAN CONCERTADO'!AH14 -> X | AI14: ='PLAN CONCERTADO'!AI14 -> X | AJ14: ='PLAN CONCERTADO'!AJ14 | AK14: ='PLAN CONCERTADO'!AK14 | AL14: ='PLAN CONCERTADO'!AL14 -> X | AM14: ='PLAN CONCERTADO'!AM14 -> 45894 | AO14: ='PLAN CONCERTADO'!AO14 | AP14: ='PLAN CONCERTADO'!AP14 -> X
W15: ='PLAN CONCERTADO'!W15 -> Incorporar seguridad a la API REST de la aplicación web | AB15: ='PLAN CONCERTADO'!AB15 -> API REST Segura | AH15: ='PLAN CONCERTADO'!AH15 -> X | AI15: ='PLAN CONCERTADO'!AI15 -> X | AJ15: ='PLAN CONCERTADO'!AJ15 | AK15: ='PLAN CONCERTADO'!AK15 | AL15: ='PLAN CONCERTADO'!AL15 -> X | AM15: ='PLAN CONCERTADO'!AM15 -> 45915 | AO15: ='PLAN CONCERTADO'!AO15 | AP15: ='PLAN CONCERTADO'!AP15 -> X
W16: ='PLAN CONCERTADO'!W16 -> Desarrollar la aplicación web | AB16: ='PLAN CONCERTADO'!AB16 -> Aplicación Web (80%) | AH16: ='PLAN CONCERTADO'!AH16 -> X | AI16: ='PLAN CONCERTADO'!AI16 -> X | AJ16: ='PLAN CONCERTADO'!AJ16 | AK16: ='PLAN CONCERTADO'!AK16 | AL16: ='PLAN CONCERTADO'!AL16 -> X | AM16: ='PLAN CONCERTADO'!AM16 -> 45915 | AO16: ='PLAN CONCERTADO'!AO16 | AP16: ='PLAN CONCERTADO'!AP16 -> X
G17: ='PLAN CONCERTADO'!G17 -> ( COMPETENCIAS DEL TRIMESTRE ) | O17: ='PLAN CONCERTADO'!O17 -> ( RESULTADOS DE APRENDIZAJE DEL TRIMESTRE ) | W17: ='PLAN CONCERTADO'!W17 -> EVALUACIÓN DE CONOCIMIENTO | AB17: ='PLAN CONCERTADO'!AB17 -> Presentación Evaluación de Conocimiento | AH17: ='PLAN CONCERTADO'!AH17 -> X | AI17: ='PLAN CONCERTADO'!AI17 | AJ17: ='PLAN CONCERTADO'!AJ17 | AK17: ='PLAN CONCERTADO'!AK17 | AL17: ='PLAN CONCERTADO'!AL17 -> X | AM17: ='PLAN CONCERTADO'!AM17 -> 45915 | AO17: ='PLAN CONCERTADO'!AO17 | AP17: ='PLAN CONCERTADO'!AP17 -> X
W18: ='PLAN CONCERTADO'!W18 -> PRE-SUSTENTACIÓN | AB18: ='PLAN CONCERTADO'!AB18 -> Entregables Proyecto | AH18: ='PLAN CONCERTADO'!AH18 | AI18: ='PLAN CONCERTADO'!AI18 -> X | AJ18: ='PLAN CONCERTADO'!AJ18 | AK18: ='PLAN CONCERTADO'!AK18 | AL18: ='PLAN CONCERTADO'!AL18 -> X | AM18: ='PLAN CONCERTADO'!AM18 -> 45922 | AO18: ='PLAN CONCERTADO'!AO18 | AP18: ='PLAN CONCERTADO'!AP18 -> X
W19: ='PLAN CONCERTADO'!W19 -> SUSTENTACIÓN | AB19: ='PLAN CONCERTADO'!AB19 -> Entregables Proyecto | AH19: ='PLAN CONCERTADO'!AH19 | AI19: ='PLAN CONCERTADO'!AI19 -> X | AJ19: ='PLAN CONCERTADO'!AJ19 | AK19: ='PLAN CONCERTADO'!AK19 | AL19: ='PLAN CONCERTADO'!AL19 -> X | AM19: ='PLAN CONCERTADO'!AM19 -> 45924 | AO19: ='PLAN CONCERTADO'!AO19 | AP19: ='PLAN CONCERTADO'!AP19 -> X
W20: ='PLAN CONCERTADO'!W20 -> AJUSTES PROYECTO Y CIERRE DE TRIMESTRE | AB20: ='PLAN CONCERTADO'!AB20 -> Ajuste de los entregables del Proyecto | AH20: ='PLAN CONCERTADO'!AH20 | AI20: ='PLAN CONCERTADO'!AI20 -> X | AJ20: ='PLAN CONCERTADO'!AJ20 | AK20: ='PLAN CONCERTADO'!AK20 | AL20: ='PLAN CONCERTADO'!AL20 -> X | AM20: ='PLAN CONCERTADO'!AM20 -> 45936 | AO20: ='PLAN CONCERTADO'!AO20 | AP20: ='PLAN CONCERTADO'!AP20 -> X

Sheet 6
A1: FORMATO PLAN CONCERTADO DE LA RUTA DE APRENDIZAJE
A2: Instructor | D2: EDWIN ALBEIRO RAMOS VILLAMIL | P2: Trimestre del año | T2: III
A3: Programa de Formación | F3: ANÁLISIS Y DESARROLLO DE SOFTWARE | P3: Trimestre Formación | T3: V
A4: Nivel | C4: TECNÓLOGO | E4: Ficha | G4: 2996150 | J4: Jornada | M4: DIURNA | P4: Fecha Concertación | T4: 45866
A7: Aprendiz | G7: Competencia | O7: Resultado de Aprendizaje | W7: Temática | AB7: Evidencia de Aprendizaje | AH7: Tipo de Evidencia | AK7: Formato de Entrega | AM7: Fecha de Entrega | AO7: Entregó
AH8: EC | AI8: ED | AJ8: EP | AK8: Físico | AL8: Digital | AO8: Sí | AP8: No
A9: ='PLAN CONCERTADO'!B14 -> YOJAN SNEYDER FLOREZ SANCHEZ | G9: ='PLAN CONCERTADO'!G9 -> ( COMPETENCIAS TÉCNICAS TRANSVERSALES) | O9: ='PLAN CONCERTADO'!O9 -> ( RESULTADOS DE APRENDIZAJE DEL TRIMESTRE ) | W9: ='PLAN CONCERTADO'!W9 -> Presentación del Trimestre: Instructor, Competencias, Resultados, Evidencias, Metodología, Normas y Seguimiento Académico. | AB9: ='PLAN CONCERTADO'!AB9 -> Cronograma de Actividades | AH9: ='PLAN CONCERTADO'!AH9 -> X | AI9: ='PLAN CONCERTADO'!AI9 -> X | AJ9: ='PLAN CONCERTADO'!AJ9 -> X | AK9: ='PLAN CONCERTADO'!AK9 | AL9: ='PLAN CONCERTADO'!AL9 -> X | AM9: ='PLAN CONCERTADO'!AM9 -> 45873 | AO9: ='PLAN CONCERTADO'!AO9 | AP9: ='PLAN CONCERTADO'!AP9 -> X
W10: ='PLAN CONCERTADO'!W10 -> Ajustar el Portafolio del Aprendiz | AB10: ='PLAN CONCERTADO'!AB10 -> Portafolio del Aprendiz con Evidencias de los Trimestres | AH10: ='PLAN CONCERTADO'!AH10 -> X | AI10: ='PLAN CONCERTADO'!AI10 -> X | AJ10: ='PLAN CONCERTADO'!AJ10 -> X | AK10: ='PLAN CONCERTADO'!AK10 | AL10: ='PLAN CONCERTADO'!AL10 -> X | AM10: ='PLAN CONCERTADO'!AM10 -> 45873 | AO10: ='PLAN CONCERTADO'!AO10 | AP10: ='PLAN CONCERTADO'!AP10 -> X
W11: ='PLAN CONCERTADO'!W11 -> Organizar el Sistema Control de Versiones | AB11: ='PLAN CONCERTADO'!AB11 -> Sistema Control Versiones con Entregables Proyecto | AH11: ='PLAN CONCERTADO'!AH11 -> X | AI11: ='PLAN CONCERTADO'!AI11 -> X | AJ11: ='PLAN CONCERTADO'!AJ11 -> X | AK11: ='PLAN CONCERTADO'!AK11 | AL11: ='PLAN CONCERTADO'!AL11 -> X | AM11: ='PLAN CONCERTADO'!AM11 -> 45873 | AO11: ='PLAN CONCERTADO'!AO11 | AP11: ='PLAN CONCERTADO'!AP11 -> X
W12: ='PLAN CONCERTADO'!W12 -> Verificar la calidad de las evidencias del proyecto software de trimestres anteriores | AB12: ='PLAN CONCERTADO'!AB12 -> Evidencias del Proyecto de Trimestres Anteriores | AH12: ='PLAN CONCERTADO'!AH12 -> X | AI12: ='PLAN CONCERTADO'!AI12 -> X | AJ12: ='PLAN CONCERTADO'!AJ12 -> X | AK12: ='PLAN CONCERTADO'!AK12 | AL12: ='PLAN CONCERTADO'!AL12 -> X | AM12: ='PLAN CONCERTADO'!AM12 -> 45873 | AO12: ='PLAN CONCERTADO'!AO12 | AP12: ='PLAN CONCERTADO'!AP12 -> X
G13: ='PLAN CONCERTADO'!G13 -> 220501096 DESARROLLAR LA SOLUCIÓN DE SOFTWARE DE ACUERDO CON EL DISEÑO Y METODOLOGÍAS DE DESARROLLO | O13: ='PLAN CONCERTADO'!O13 -> 220501096_04 CODIFICAR EL SOFTWARE DE ACUERDO CON EL DISEÑO ESTABLECIDO | W13: ='PLAN CONCERTADO'!W13 -> Desarrollar las API REST de la aplicación web | AB13: ='PLAN CONCERTADO'!AB13 -> API REST | AH13: ='PLAN CONCERTADO'!AH13 -> X | AI13: ='PLAN CONCERTADO'!AI13 -> X | AJ13: ='PLAN CONCERTADO'!AJ13 | AK13: ='PLAN CONCERTADO'!AK13 | AL13: ='PLAN CONCERTADO'!AL13 -> X | AM13: ='PLAN CONCERTADO'!AM13 -> 45894 | AO13: ='PLAN CONCERTADO'!AO13 | AP13: ='PLAN CONCERTADO'!AP13 -> X
W14: ='PLAN CONCERTADO'!W14 -> Desarrollo de Frontend de la aplicación web con React, Angular o Vue basado en el diseño web | AB14: ='PLAN CONCERTADO'!AB14 -> Frontend JS | AH14: ='PLAN CONCERTADO'!AH14 -> X | AI14: ='PLAN CONCERTADO'!AI14 -> X | AJ14: ='PLAN CONCERTADO'!AJ14 | AK14: ='PLAN CONCERTADO'!AK14 | AL14: ='PLAN CONCERTADO'!AL14 -> X | AM14: ='PLAN CONCERTADO'!AM14 -> 45894 | AO14: ='PLAN CONCERTADO'!AO14 | AP14: ='PLAN CONCERTADO'!AP14 -> X
W15: ='PLAN CONCERTADO'!W15 -> Incorporar seguridad a la API REST de la aplicación web | AB15: ='PLAN CONCERTADO'!AB15 -> API REST Segura | AH15: ='PLAN CONCERTADO'!AH15 -> X | AI15: ='PLAN CONCERTADO'!AI15 -> X | AJ15: ='PLAN CONCERTADO'!AJ15 | AK15: ='PLAN CONCERTADO'!AK15 | AL15: ='PLAN CONCERTADO'!AL15 -> X | AM15: ='PLAN CONCERTADO'!AM15 -> 45915 | AO15: ='PLAN CONCERTADO'!AO15 | AP15: ='PLAN CONCERTADO'!AP15 -> X
W16: ='PLAN CONCERTADO'!W16 -> Desarrollar la aplicación web | AB16: ='PLAN CONCERTADO'!AB16 -> Aplicación Web (80%) | AH16: ='PLAN CONCERTADO'!AH16 -> X | AI16: ='PLAN CONCERTADO'!AI16 -> X | AJ16: ='PLAN CONCERTADO'!AJ16 | AK16: ='PLAN CONCERTADO'!AK16 | AL16: ='PLAN CONCERTADO'!AL16 -> X | AM16: ='PLAN CONCERTADO'!AM16 -> 45915 | AO16: ='PLAN CONCERTADO'!AO16 | AP16: ='PLAN CONCERTADO'!AP16 -> X
G17: ='PLAN CONCERTADO'!G17 -> ( COMPETENCIAS DEL TRIMESTRE ) | O17: ='PLAN CONCERTADO'!O17 -> ( RESULTADOS DE APRENDIZAJE DEL TRIMESTRE ) | W17: ='PLAN CONCERTADO'!W17 -> EVALUACIÓN DE CONOCIMIENTO | AB17: ='PLAN CONCERTADO'!AB17 -> Presentación Evaluación de Conocimiento | AH17: ='PLAN CONCERTADO'!AH17 -> X | AI17: ='PLAN CONCERTADO'!AI17 | AJ17: ='PLAN CONCERTADO'!AJ17 | AK17: ='PLAN CONCERTADO'!AK17 | AL17: ='PLAN CONCERTADO'!AL17 -> X | AM17: ='PLAN CONCERTADO'!AM17 -> 45915 | AO17: ='PLAN CONCERTADO'!AO17 | AP17: ='PLAN CONCERTADO'!AP17 -> X
W18: ='PLAN CONCERTADO'!W18 -> PRE-SUSTENTACIÓN | AB18: ='PLAN CONCERTADO'!AB18 -> Entregables Proyecto | AH18: ='PLAN CONCERTADO'!AH18 | AI18: ='PLAN CONCERTADO'!AI18 -> X | AJ18: ='PLAN CONCERTADO'!AJ18 | AK18: ='PLAN CONCERTADO'!AK18 | AL18: ='PLAN CONCERTADO'!AL18 -> X | AM18: ='PLAN CONCERTADO'!AM18 -> 45922 | AO18: ='PLAN CONCERTADO'!AO18 | AP18: ='PLAN CONCERTADO'!AP18 -> X
W19: ='PLAN CONCERTADO'!W19 -> SUSTENTACIÓN | AB19: ='PLAN CONCERTADO'!AB19 -> Entregables Proyecto | AH19: ='PLAN CONCERTADO'!AH19 | AI19: ='PLAN CONCERTADO'!AI19 -> X | AJ19: ='PLAN CONCERTADO'!AJ19 | AK19: ='PLAN CONCERTADO'!AK19 | AL19: ='PLAN CONCERTADO'!AL19 -> X | AM19: ='PLAN CONCERTADO'!AM19 -> 45924 | AO19: ='PLAN CONCERTADO'!AO19 | AP19: ='PLAN CONCERTADO'!AP19 -> X
W20: ='PLAN CONCERTADO'!W20 -> AJUSTES PROYECTO Y CIERRE DE TRIMESTRE | AB20: ='PLAN CONCERTADO'!AB20 -> Ajuste de los entregables del Proyecto | AH20: ='PLAN CONCERTADO'!AH20 | AI20: ='PLAN CONCERTADO'!AI20 -> X | AJ20: ='PLAN CONCERTADO'!AJ20 | AK20: ='PLAN CONCERTADO'!AK20 | AL20: ='PLAN CONCERTADO'!AL20 -> X | AM20: ='PLAN CONCERTADO'!AM20 -> 45936 | AO20: ='PLAN CONCERTADO'!AO20 | AP20: ='PLAN CONCERTADO'!AP20 -> X

Sheet 7
A1: FORMATO PLAN CONCERTADO DE LA RUTA DE APRENDIZAJE
A2: Instructor | D2: EDWIN ALBEIRO RAMOS VILLAMIL | P2: Trimestre del año | T2: III
A3: Programa de Formación | F3: ANÁLISIS Y DESARROLLO DE SOFTWARE | P3: Trimestre Formación | T3: V
A4: Nivel | C4: TECNÓLOGO | E4: Ficha | G4: 2996150 | J4: Jornada | M4: DIURNA | P4: Fecha Concertación | T4: 45866
A7: Aprendiz | G7: Competencia | O7: Resultado de Aprendizaje | W7: Temática | AB7: Evidencia de Aprendizaje | AH7: Tipo de Evidencia | AK7: Formato de Entrega | AM7: Fecha de Entrega | AO7: Entregó
AH8: EC | AI8: ED | AJ8: EP | AK8: Físico | AL8: Digital | AO8: Sí | AP8: No
A9: ='PLAN CONCERTADO'!B15 -> DAVID SANTIAGO FUQUENE LEAL | G9: ='PLAN CONCERTADO'!G9 -> ( COMPETENCIAS TÉCNICAS TRANSVERSALES) | O9: ='PLAN CONCERTADO'!O9 -> ( RESULTADOS DE APRENDIZAJE DEL TRIMESTRE ) | W9: ='PLAN CONCERTADO'!W9 -> Presentación del Trimestre: Instructor, Competencias, Resultados, Evidencias, Metodología, Normas y Seguimiento Académico. | AB9: ='PLAN CONCERTADO'!AB9 -> Cronograma de Actividades | AH9: ='PLAN CONCERTADO'!AH9 -> X | AI9: ='PLAN CONCERTADO'!AI9 -> X | AJ9: ='PLAN CONCERTADO'!AJ9 -> X | AK9: ='PLAN CONCERTADO'!AK9 | AL9: ='PLAN CONCERTADO'!AL9 -> X | AM9: ='PLAN CONCERTADO'!AM9 -> 45873 | AO9: ='PLAN CONCERTADO'!AO9 | AP9: ='PLAN CONCERTADO'!AP9 -> X
W10: ='PLAN CONCERTADO'!W10 -> Ajustar el Portafolio del Aprendiz | AB10: ='PLAN CONCERTADO'!AB10 -> Portafolio del Aprendiz con Evidencias de los Trimestres | AH10: ='PLAN CONCERTADO'!AH10 -> X | AI10: ='PLAN CONCERTADO'!AI10 -> X | AJ10: ='PLAN CONCERTADO'!AJ10 -> X | AK10: ='PLAN CONCERTADO'!AK10 | AL10: ='PLAN CONCERTADO'!AL10 -> X | AM10: ='PLAN CONCERTADO'!AM10 -> 45873 | AO10: ='PLAN CONCERTADO'!AO10 | AP10: ='PLAN CONCERTADO'!AP10 -> X
W11: ='PLAN CONCERTADO'!W11 -> Organizar el Sistema Control de Versiones | AB11: ='PLAN CONCERTADO'!AB11 -> Sistema Control Versiones con Entregables Proyecto | AH11: ='PLAN CONCERTADO'!AH11 -> X | AI11: ='PLAN CONCERTADO'!AI11 -> X | AJ11: ='PLAN CONCERTADO'!AJ11 -> X | AK11: ='PLAN CONCERTADO'!AK11 | AL11: ='PLAN CONCERTADO'!AL11 -> X | AM11: ='PLAN CONCERTADO'!AM11 -> 45873 | AO11: ='PLAN CONCERTADO'!AO11 | AP11: ='PLAN CONCERTADO'!AP11 -> X
W12: ='PLAN CONCERTADO'!W12 -> Verificar la calidad de las evidencias del proyecto software de trimestres anteriores | AB12: ='PLAN CONCERTADO'!AB12 -> Evidencias del Proyecto de Trimestres Anteriores | AH12: ='PLAN CONCERTADO'!AH12 -> X | AI12: ='PLAN CONCERTADO'!AI12 -> X | AJ12: ='PLAN CONCERTADO'!AJ12 -> X | AK12: ='PLAN CONCERTADO'!AK12 | AL12: ='PLAN CONCERTADO'!AL12 -> X | AM12: ='PLAN CONCERTADO'!AM12 -> 45873 | AO12: ='PLAN CONCERTADO'!AO12 | AP12: ='PLAN CONCERTADO'!AP12 -> X
G13: ='PLAN CONCERTADO'!G13 -> 220501096 DESARROLLAR LA SOLUCIÓN DE SOFTWARE DE ACUERDO CON EL DISEÑO Y METODOLOGÍAS DE DESARROLLO | O13: ='PLAN CONCERTADO'!O13 -> 220501096_04 CODIFICAR EL SOFTWARE DE ACUERDO CON EL DISEÑO ESTABLECIDO | W13: ='PLAN CONCERTADO'!W13 -> Desarrollar las API REST de la aplicación web | AB13: ='PLAN CONCERTADO'!AB13 -> API REST | AH13: ='PLAN CONCERTADO'!AH13 -> X | AI13: ='PLAN CONCERTADO'!AI13 -> X | AJ13: ='PLAN CONCERTADO'!AJ13 | AK13: ='PLAN CONCERTADO'!AK13 | AL13: ='PLAN CONCERTADO'!AL13 -> X | AM13: ='PLAN CONCERTADO'!AM13 -> 45894 | AO13: ='PLAN CONCERTADO'!AO13 | AP13: ='PLAN CONCERTADO'!AP13 -> X
W14: ='PLAN CONCERTADO'!W14 -> Desarrollo de Frontend de la aplicación web con React, Angular o Vue basado en el diseño web | AB14: ='PLAN CONCERTADO'!AB14 -> Frontend JS | AH14: ='PLAN CONCERTADO'!AH14 -> X | AI14: ='PLAN CONCERTADO'!AI14 -> X | AJ14: ='PLAN CONCERTADO'!AJ14 | AK14: ='PLAN CONCERTADO'!AK14 | AL14: ='PLAN CONCERTADO'!AL14 -> X | AM14: ='PLAN CONCERTADO'!AM14 -> 45894 | AO14: ='PLAN CONCERTADO'!AO14 | AP14: ='PLAN CONCERTADO'!AP14 -> X
W15: ='PLAN CONCERTADO'!W15 -> Incorporar seguridad a la API REST de la aplicación web | AB15: ='PLAN CONCERTADO'!AB15 -> API REST Segura | AH15: ='PLAN CONCERTADO'!AH15 -> X | AI15: ='PLAN CONCERTADO'!AI15 -> X | AJ15: ='PLAN CONCERTADO'!AJ15 | AK15: ='PLAN CONCERTADO'!AK15 | AL15: ='PLAN CONCERTADO'!AL15 -> X | AM15: ='PLAN CONCERTADO'!AM15 -> 45915 | AO15: ='PLAN CONCERTADO'!AO15 | AP15: ='PLAN CONCERTADO'!AP15 -> X
W16: ='PLAN CONCERTADO'!W16 -> Desarrollar la aplicación web | AB16: ='PLAN CONCERTADO'!AB16 -> Aplicación Web (80%) | AH16: ='PLAN CONCERTADO'!AH16 -> X | AI16: ='PLAN CONCERTADO'!AI16 -> X | AJ16: ='PLAN CONCERTADO'!AJ16 | AK16: ='PLAN CONCERTADO'!AK16 | AL16: ='PLAN CONCERTADO'!AL16 -> X | AM16: ='PLAN CONCERTADO'!AM16 -> 45915 | AO16: ='PLAN CONCERTADO'!AO16 | AP16: ='PLAN CONCERTADO'!AP16 -> X
G17: ='PLAN CONCERTADO'!G17 -> ( COMPETENCIAS DEL TRIMESTRE ) | O17: ='PLAN CONCERTADO'!O17 -> ( RESULTADOS DE APRENDIZAJE DEL TRIMESTRE ) | W17: ='PLAN CONCERTADO'!W17 -> EVALUACIÓN DE CONOCIMIENTO | AB17: ='PLAN CONCERTADO'!AB17 -> Presentación Evaluación de Conocimiento | AH17: ='PLAN CONCERTADO'!AH17 -> X | AI17: ='PLAN CONCERTADO'!AI17 | AJ17: ='PLAN CONCERTADO'!AJ17 | AK17: ='PLAN CONCERTADO'!AK17 | AL17: ='PLAN CONCERTADO'!AL17 -> X | AM17: ='PLAN CONCERTADO'!AM17 -> 45915 | AO17: ='PLAN CONCERTADO'!AO17 | AP17: ='PLAN CONCERTADO'!AP17 -> X
W18: ='PLAN CONCERTADO'!W18 -> PRE-SUSTENTACIÓN | AB18: ='PLAN CONCERTADO'!AB18 -> Entregables Proyecto | AH18: ='PLAN CONCERTADO'!AH18 | AI18: ='PLAN CONCERTADO'!AI18 -> X | AJ18: ='PLAN CONCERTADO'!AJ18 | AK18: ='PLAN CONCERTADO'!AK18 | AL18: ='PLAN CONCERTADO'!AL18 -> X | AM18: ='PLAN CONCERTADO'!AM18 -> 45922 | AO18: ='PLAN CONCERTADO'!AO18 | AP18: ='PLAN CONCERTADO'!AP18 -> X
W19: ='PLAN CONCERTADO'!W19 -> SUSTENTACIÓN | AB19: ='PLAN CONCERTADO'!AB19 -> Entregables Proyecto | AH19: ='PLAN CONCERTADO'!AH19 | AI19: ='PLAN CONCERTADO'!AI19 -> X | AJ19: ='PLAN CONCERTADO'!AJ19 | AK19: ='PLAN CONCERTADO'!AK19 | AL19: ='PLAN CONCERTADO'!AL19 -> X | AM19: ='PLAN CONCERTADO'!AM19 -> 45924 | AO19: ='PLAN CONCERTADO'!AO19 | AP19: ='PLAN CONCERTADO'!AP19 -> X
W20: ='PLAN CONCERTADO'!W20 -> AJUSTES PROYECTO Y CIERRE DE TRIMESTRE | AB20: ='PLAN CONCERTADO'!AB20 -> Ajuste de los entregables del Proyecto | AH20: ='PLAN CONCERTADO'!AH20 | AI20: ='PLAN CONCERTADO'!AI20 -> X | AJ20: ='PLAN CONCERTADO'!AJ20 | AK20: ='PLAN CONCERTADO'!AK20 | AL20: ='PLAN CONCERTADO'!AL20 -> X | AM20: ='PLAN CONCERTADO'!AM20 -> 45936 | AO20: ='PLAN CONCERTADO'!AO20 | AP20: ='PLAN CONCERTADO'!AP20 -> X

Sheet 8
A1: FORMATO PLAN CONCERTADO DE LA RUTA DE APRENDIZAJE
A2: Instructor | D2: EDWIN ALBEIRO RAMOS VILLAMIL | P2: Trimestre del año | T2: III
A3: Programa de Formación | F3: ANÁLISIS Y DESARROLLO DE SOFTWARE | P3: Trimestre Formación | T3: V
A4: Nivel | C4: TECNÓLOGO | E4: Ficha | G4: 2996150 | J4: Jornada | M4: DIURNA | P4: Fecha Concertación | T4: 45866
A7: Aprendiz | G7: Competencia | O7: Resultado de Aprendizaje | W7: Temática | AB7: Evidencia de Aprendizaje | AH7: Tipo de Evidencia | AK7: Formato de Entrega | AM7: Fecha de Entrega | AO7: Entregó
AH8: EC | AI8: ED | AJ8: EP | AK8: Físico | AL8: Digital | AO8: Sí | AP8: No
A9: ='PLAN CONCERTADO'!B16 -> OSCAR DAVID GELPUD ERAZO | G9: ='PLAN CONCERTADO'!G9 -> ( COMPETENCIAS TÉCNICAS TRANSVERSALES) | O9: ='PLAN CONCERTADO'!O9 -> ( RESULTADOS DE APRENDIZAJE DEL TRIMESTRE ) | W9: ='PLAN CONCERTADO'!W9 -> Presentación del Trimestre: Instructor, Competencias, Resultados, Evidencias, Metodología, Normas y Seguimiento Académico. | AB9: ='PLAN CONCERTADO'!AB9 -> Cronograma de Actividades | AH9: ='PLAN CONCERTADO'!AH9 -> X | AI9: ='PLAN CONCERTADO'!AI9 -> X | AJ9: ='PLAN CONCERTADO'!AJ9 -> X | AK9: ='PLAN CONCERTADO'!AK9 | AL9: ='PLAN CONCERTADO'!AL9 -> X | AM9: ='PLAN CONCERTADO'!AM9 -> 45873 | AO9: ='PLAN CONCERTADO'!AO9 | AP9: ='PLAN CONCERTADO'!AP9 -> X
W10: ='PLAN CONCERTADO'!W10 -> Ajustar el Portafolio del Aprendiz | AB10: ='PLAN CONCERTADO'!AB10 -> Portafolio del Aprendiz con Evidencias de los Trimestres | AH10: ='PLAN CONCERTADO'!AH10 -> X | AI10: ='PLAN CONCERTADO'!AI10 -> X | AJ10: ='PLAN CONCERTADO'!AJ10 -> X | AK10: ='PLAN CONCERTADO'!AK10 | AL10: ='PLAN CONCERTADO'!AL10 -> X | AM10: ='PLAN CONCERTADO'!AM10 -> 45873 | AO10: ='PLAN CONCERTADO'!AO10 | AP10: ='PLAN CONCERTADO'!AP10 -> X
W11: ='PLAN CONCERTADO'!W11 -> Organizar el Sistema Control de Versiones | AB11: ='PLAN CONCERTADO'!AB11 -> Sistema Control Versiones con Entregables Proyecto | AH11: ='PLAN CONCERTADO'!AH11 -> X | AI11: ='PLAN CONCERTADO'!AI11 -> X | AJ11: ='PLAN CONCERTADO'!AJ11 -> X | AK11: ='PLAN CONCERTADO'!AK11 | AL11: ='PLAN CONCERTADO'!AL11 -> X | AM11: ='PLAN CONCERTADO'!AM11 -> 45873 | AO11: ='PLAN CONCERTADO'!AO11 | AP11: ='PLAN CONCERTADO'!AP11 -> X
W12: ='PLAN CONCERTADO'!W12 -> Verificar la calidad de las evidencias del proyecto software de trimestres anteriores | AB12: ='PLAN CONCERTADO'!AB12 -> Evidencias del Proyecto de Trimestres Anteriores | AH12: ='PLAN CONCERTADO'!AH12 -> X | AI12: ='PLAN CONCERTADO'!AI12 -> X | AJ12: ='PLAN CONCERTADO'!AJ12 -> X | AK12: ='PLAN CONCERTADO'!AK12 | AL12: ='PLAN CONCERTADO'!AL12 -> X | AM12: ='PLAN CONCERTADO'!AM12 -> 45873 | AO12: ='PLAN CONCERTADO'!AO12 | AP12: ='PLAN CONCERTADO'!AP12 -> X
G13: ='PLAN CONCERTADO'!G13 -> 220501096 DESARROLLAR LA SOLUCIÓN DE SOFTWARE DE ACUERDO CON EL DISEÑO Y METODOLOGÍAS DE DESARROLLO | O13: ='PLAN CONCERTADO'!O13 -> 220501096_04 CODIFICAR EL SOFTWARE DE ACUERDO CON EL DISEÑO ESTABLECIDO | W13: ='PLAN CONCERTADO'!W13 -> Desarrollar las API REST de la aplicación web | AB13: ='PLAN CONCERTADO'!AB13 -> API REST | AH13: ='PLAN CONCERTADO'!AH13 -> X | AI13: ='PLAN CONCERTADO'!AI13 -> X | AJ13: ='PLAN CONCERTADO'!AJ13 | AK13: ='PLAN CONCERTADO'!AK13 | AL13: ='PLAN CONCERTADO'!AL13 -> X | AM13: ='PLAN CONCERTADO'!AM13 -> 45894 | AO13: ='PLAN CONCERTADO'!AO13 | AP13: ='PLAN CONCERTADO'!AP13 -> X
W14: ='PLAN CONCERTADO'!W14 -> Desarrollo de Frontend de la aplicación web con React, Angular o Vue basado en el diseño web | AB14: ='PLAN CONCERTADO'!AB14 -> Frontend JS | AH14: ='PLAN CONCERTADO'!AH14 -> X | AI14: ='PLAN CONCERTADO'!AI14 -> X | AJ14: ='PLAN CONCERTADO'!AJ14 | AK14: ='PLAN CONCERTADO'!AK14 | AL14: ='PLAN CONCERTADO'!AL14 -> X | AM14: ='PLAN CONCERTADO'!AM14 -> 45894 | AO14: ='PLAN CONCERTADO'!AO14 | AP14: ='PLAN CONCERTADO'!AP14 -> X
W15: ='PLAN CONCERTADO'!W15 -> Incorporar seguridad a la API REST de la aplicación web | AB15: ='PLAN CONCERTADO'!AB15 -> API REST Segura | AH15: ='PLAN CONCERTADO'!AH15 -> X | AI15: ='PLAN CONCERTADO'!AI15 -> X | AJ15: ='PLAN CONCERTADO'!AJ15 | AK15: ='PLAN CONCERTADO'!AK15 | AL15: ='PLAN CONCERTADO'!AL15 -> X | AM15: ='PLAN CONCERTADO'!AM15 -> 45915 | AO15: ='PLAN CONCERTADO'!AO15 | AP15: ='PLAN CONCERTADO'!AP15 -> X
W16: ='PLAN CONCERTADO'!W16 -> Desarrollar la aplicación web | AB16: ='PLAN CONCERTADO'!AB16 -> Aplicación Web (80%) | AH16: ='PLAN CONCERTADO'!AH16 -> X | AI16: ='PLAN CONCERTADO'!AI16 -> X | AJ16: ='PLAN CONCERTADO'!AJ16 | AK16: ='PLAN CONCERTADO'!AK16 | AL16: ='PLAN CONCERTADO'!AL16 -> X | AM16: ='PLAN CONCERTADO'!AM16 -> 45915 | AO16: ='PLAN CONCERTADO'!AO16 | AP16: ='PLAN CONCERTADO'!AP16 -> X
G17: ='PLAN CONCERTADO'!G17 -> ( COMPETENCIAS DEL TRIMESTRE ) | O17: ='PLAN CONCERTADO'!O17 -> ( RESULTADOS DE APRENDIZAJE DEL TRIMESTRE ) | W17: ='PLAN CONCERTADO'!W17 -> EVALUACIÓN DE CONOCIMIENTO | AB17: ='PLAN CONCERTADO'!AB17 -> Presentación Evaluación de Conocimiento | AH17: ='PLAN CONCERTADO'!AH17 -> X | AI17: ='PLAN CONCERTADO'!AI17 | AJ17: ='PLAN CONCERTADO'!AJ17 | AK17: ='PLAN CONCERTADO'!AK17 | AL17: ='PLAN CONCERTADO'!AL17 -> X | AM17: ='PLAN CONCERTADO'!AM17 -> 45915 | AO17: ='PLAN CONCERTADO'!AO17 | AP17: ='PLAN CONCERTADO'!AP17 -> X
W18: ='PLAN CONCERTADO'!W18 -> PRE-SUSTENTACIÓN | AB18: ='PLAN CONCERTADO'!AB18 -> Entregables Proyecto | AH18: ='PLAN CONCERTADO'!AH18 | AI18: ='PLAN CONCERTADO'!AI18 -> X | AJ18: ='PLAN CONCERTADO'!AJ18 | AK18: ='PLAN CONCERTADO'!AK18 | AL18: ='PLAN CONCERTADO'!AL18 -> X | AM18: ='PLAN CONCERTADO'!AM18 -> 45922 | AO18: ='PLAN CONCERTADO'!AO18 | AP18: ='PLAN CONCERTADO'!AP18 -> X
W19: ='PLAN CONCERTADO'!W19 -> SUSTENTACIÓN | AB19: ='PLAN CONCERTADO'!AB19 -> Entregables Proyecto | AH19: ='PLAN CONCERTADO'!AH19 | AI19: ='PLAN CONCERTADO'!AI19 -> X | AJ19: ='PLAN CONCERTADO'!AJ19 | AK19: ='PLAN CONCERTADO'!AK19 | AL19: ='PLAN CONCERTADO'!AL19 -> X | AM19: ='PLAN CONCERTADO'!AM19 -> 45924 | AO19: ='PLAN CONCERTADO'!AO19 | AP19: ='PLAN CONCERTADO'!AP19 -> X
W20: ='PLAN CONCERTADO'!W20 -> AJUSTES PROYECTO Y CIERRE DE TRIMESTRE | AB20: ='PLAN CONCERTADO'!AB20 -> Ajuste de los entregables del Proyecto | AH20: ='PLAN CONCERTADO'!AH20 | AI20: ='PLAN CONCERTADO'!AI20 -> X | AJ20: ='PLAN CONCERTADO'!AJ20 | AK20: ='PLAN CONCERTADO'!AK20 | AL20: ='PLAN CONCERTADO'!AL20 -> X | AM20: ='PLAN CONCERTADO'!AM20 -> 45936 | AO20: ='PLAN CONCERTADO'!AO20 | AP20: ='PLAN CONCERTADO'!AP20 -> X

Sheet 9
A1: FORMATO PLAN CONCERTADO DE LA RUTA DE APRENDIZAJE
A2: Instructor | D2: EDWIN ALBEIRO RAMOS VILLAMIL | P2: Trimestre del año | T2: III
A3: Programa de Formación | F3: ANÁLISIS Y DESARROLLO DE SOFTWARE | P3: Trimestre Formación | T3: V
A4: Nivel | C4: TECNÓLOGO | E4: Ficha | G4: 2996150 | J4: Jornada | M4: DIURNA | P4: Fecha Concertación | T4: 45866
A7: Aprendiz | G7: Competencia | O7: Resultado de Aprendizaje | W7: Temática | AB7: Evidencia de Aprendizaje | AH7: Tipo de Evidencia | AK7: Formato de Entrega | AM7: Fecha de Entrega | AO7: Entregó
AH8: EC | AI8: ED | AJ8: EP | AK8: Físico | AL8: Digital | AO8: Sí | AP8: No
A9: ='PLAN CONCERTADO'!B17 -> KAREN DANIELA LEAL POVEDA | G9: ='PLAN CONCERTADO'!G9 -> ( COMPETENCIAS TÉCNICAS TRANSVERSALES) | O9: ='PLAN CONCERTADO'!O9 -> ( RESULTADOS DE APRENDIZAJE DEL TRIMESTRE ) | W9: ='PLAN CONCERTADO'!W9 -> Presentación del Trimestre: Instructor, Competencias, Resultados, Evidencias, Metodología, Normas y Seguimiento Académico. | AB9: ='PLAN CONCERTADO'!AB9 -> Cronograma de Actividades | AH9: ='PLAN CONCERTADO'!AH9 -> X | AI9: ='PLAN CONCERTADO'!AI9 -> X | AJ9: ='PLAN CONCERTADO'!AJ9 -> X | AK9: ='PLAN CONCERTADO'!AK9 | AL9: ='PLAN CONCERTADO'!AL9 -> X | AM9: ='PLAN CONCERTADO'!AM9 -> 45873 | AO9: ='PLAN CONCERTADO'!AO9 | AP9: ='PLAN CONCERTADO'!AP9 -> X
W10: ='PLAN CONCERTADO'!W10 -> Ajustar el Portafolio del Aprendiz | AB10: ='PLAN CONCERTADO'!AB10 -> Portafolio del Aprendiz con Evidencias de los Trimestres | AH10: ='PLAN CONCERTADO'!AH10 -> X | AI10: ='PLAN CONCERTADO'!AI10 -> X | AJ10: ='PLAN CONCERTADO'!AJ10 -> X | AK10: ='PLAN CONCERTADO'!AK10 | AL10: ='PLAN CONCERTADO'!AL10 -> X | AM10: ='PLAN CONCERTADO'!AM10 -> 45873 | AO10: ='PLAN CONCERTADO'!AO10 | AP10: ='PLAN CONCERTADO'!AP10 -> X
W11: ='PLAN CONCERTADO'!W11 -> Organizar el Sistema Control de Versiones | AB11: ='PLAN CONCERTADO'!AB11 -> Sistema Control Versiones con Entregables Proyecto | AH11: ='PLAN CONCERTADO'!AH11 -> X | AI11: ='PLAN CONCERTADO'!AI11 -> X | AJ11: ='PLAN CONCERTADO'!AJ11 -> X | AK11: ='PLAN CONCERTADO'!AK11 | AL11: ='PLAN CONCERTADO'!AL11 -> X | AM11: ='PLAN CONCERTADO'!AM11 -> 45873 | AO11: ='PLAN CONCERTADO'!AO11 | AP11: ='PLAN CONCERTADO'!AP11 -> X
W12: ='PLAN CONCERTADO'!W12 -> Verificar la calidad de las evidencias del proyecto software de trimestres anteriores | AB12: ='PLAN CONCERTADO'!AB12 -> Evidencias del Proyecto de Trimestres Anteriores | AH12: ='PLAN CONCERTADO'!AH12 -> X | AI12: ='PLAN CONCERTADO'!AI12 -> X | AJ12: ='PLAN CONCERTADO'!AJ12 -> X | AK12: ='PLAN CONCERTADO'!AK12 | AL12: ='PLAN CONCERTADO'!AL12 -> X | AM12: ='PLAN CONCERTADO'!AM12 -> 45873 | AO12: ='PLAN CONCERTADO'!AO12 | AP12: ='PLAN CONCERTADO'!AP12 -> X
G13: ='PLAN CONCERTADO'!G13 -> 220501096 DESARROLLAR LA SOLUCIÓN DE SOFTWARE DE ACUERDO CON EL DISEÑO Y METODOLOGÍAS DE DESARROLLO | O13: ='PLAN CONCERTADO'!O13 -> 220501096_04 CODIFICAR EL SOFTWARE DE ACUERDO CON EL DISEÑO ESTABLECIDO | W13: ='PLAN CONCERTADO'!W13 -> Desarrollar las API REST de la aplicación web | AB13: ='PLAN CONCERTADO'!AB13 -> API REST | AH13: ='PLAN CONCERTADO'!AH13 -> X | AI13: ='PLAN CONCERTADO'!AI13 -> X | AJ13: ='PLAN CONCERTADO'!AJ13 | AK13: ='PLAN CONCERTADO'!AK13 | AL13: ='PLAN CONCERTADO'!AL13 -> X | AM13: ='PLAN CONCERTADO'!AM13 -> 45894 | AO13: ='PLAN CONCERTADO'!AO13 | AP13: ='PLAN CONCERTADO'!AP13 -> X
W14: ='PLAN CONCERTADO'!W14 -> Desarrollo de Frontend de la aplicación web con React, Angular o Vue basado en el diseño web | AB14: ='PLAN CONCERTADO'!AB14 -> Frontend JS | AH14: ='PLAN CONCERTADO'!AH14 -> X | AI14: ='PLAN CONCERTADO'!AI14 -> X | AJ14: ='PLAN CONCERTADO'!AJ14 | AK14: ='PLAN CONCERTADO'!AK14 | AL14: ='PLAN CONCERTADO'!AL14 -> X | AM14: ='PLAN CONCERTADO'!AM14 -> 45894 | AO14: ='PLAN CONCERTADO'!AO14 | AP14: ='PLAN CONCERTADO'!AP14 -> X
W15: ='PLAN CONCERTADO'!W15 -> Incorporar seguridad a la API REST de la aplicación web | AB15: ='PLAN CONCERTADO'!AB15 -> API REST Segura | AH15: ='PLAN CONCERTADO'!AH15 -> X | AI15: ='PLAN CONCERTADO'!AI15 -> X | AJ15: ='PLAN CONCERTADO'!AJ15 | AK15: ='PLAN CONCERTADO'!AK15 | AL15: ='PLAN CONCERTADO'!AL15 -> X | AM15: ='PLAN CONCERTADO'!AM15 -> 45915 | AO15: ='PLAN CONCERTADO'!AO15 | AP15: ='PLAN CONCERTADO'!AP15 -> X
W16: ='PLAN CONCERTADO'!W16 -> Desarrollar la aplicación web | AB16: ='PLAN CONCERTADO'!AB16 -> Aplicación Web (80%) | AH16: ='PLAN CONCERTADO'!AH16 -> X | AI16: ='PLAN CONCERTADO'!AI16 -> X | AJ16: ='PLAN CONCERTADO'!AJ16 | AK16: ='PLAN CONCERTADO'!AK16 | AL16: ='PLAN CONCERTADO'!AL16 -> X | AM16: ='PLAN CONCERTADO'!AM16 -> 45915 | AO16: ='PLAN CONCERTADO'!AO16 | AP16: ='PLAN CONCERTADO'!AP16 -> X
